Workbook
Name ___________________b70000: #REF!
Name ___________________b70000: #REF!
Name ___________________b70000: #REF!
Name ___________________b70000: #REF!
Name ___________________b70000: #REF!
Name ___________________b70000: #REF!
Name ___________________b70000: #REF!
Name ___________________b70000: #REF!
Name ___________________b70000: #REF!
Name ___________________b70000: #REF!
Name ___________________b70000: #REF!
Name ___________________b70005: #REF!
Name ___________________b70005: #REF!
Name ___________________b70005: #REF!
Name ___________________b70005: #REF!
Name ___________________b70005: #REF!
Name ___________________b70005: #REF!
Name ___________________b70005: #REF!
Name ___________________b70005: #REF!
Name ___________________b70005: #REF!
Name ___________________b70005: #REF!
Name ___________________b70005: #REF!
Name __________________b70000: #REF!
Name __________________b70000: #REF!
Name __________________b70000: #REF!
Name __________________b70000: #REF!
Name __________________b70000: #REF!
Name __________________b70000: #REF!
Name __________________b70000: #REF!
Name __________________b70000: #REF!
Name __________________b70000: #REF!
Name __________________b70000: #REF!
Name __________________b70000: #REF!
Name __________________b70005: #REF!
Name __________________b70005: #REF!
Name __________________b70005: #REF!
Name __________________b70005: #REF!
Name __________________b70005: #REF!
Name __________________b70005: #REF!
Name __________________b70005: #REF!
Name __________________b70005: #REF!
Name __________________b70005: #REF!
Name __________________b70005: #REF!
Name __________________b70005: #REF!
Name _________________b70000: #REF!
Name _________________b70000: #REF!
Name _________________b70000: #REF!
Name _________________b70000: #REF!
Name _________________b70000: #REF!
Name _________________b70000: #REF!
Name _________________b70000: #REF!
Name _________________b70000: #REF!
Name _________________b70000: #REF!
Name _________________b70000: #REF!
Name _________________b70000: #REF!
Name _________________b70005: #REF!
Name _________________b70005: #REF!
Name _________________b70005: #REF!
Name _________________b70005: #REF!
Name _________________b70005: #REF!

Sheet CPC prévisionnel
A1: Synthèse Budget par domaine | B1: 104 | C1: 105 | D1: 106 | E1: 107 | F1: 114 | G1: 19/20 | H1: 18/19 | I1: BUD-REEL | J1: %
A2: Sup Tot (ha) | B2: =+'104_Synthèse'!N3 -> 0 | C2: =+'105_Synthèse'!N3 -> 0 | D2: =+'106_Synthèse'!N3 -> 5.575 | G2: =SUM(B2:D2) -> 5.575 | H2: =+Synthèse!O3 -> 17.3 | I2: =+G2-H2 -> -11.725 | J2: =+I2/H2 -> -0.67774566
A3: Vol (kg) | B3: =+'104_Synthèse'!N5 -> 1972475 | C3: =+'105_Synthèse'!N5 -> 728325 | D3: =+'106_Synthèse'!N5 -> 728325000 | G3: =SUM(B3:D3) -> 731025800 | H3: =+Synthèse!O5 -> 1982993.5 | I3: =+G3-H3 -> 7.2904281e+08 | J3: =+I3/H3 -> 367.6476
A4: rendement (t/ha) | B4: =+B3/B2/1000 -> #DIV/0! | C4: =+C3/C2/1000 -> #DIV/0! | D4: =+D3/D2/1000 -> 130641.26 | G4: =+G3/G2/1000 -> 131125.7 | H4: =+H3/H2/1000 -> 114.6239 | I4: =+G4-H4 -> 131011.08 | J4: =+I4/H4 -> 1142.9648
A5: Chiffre d'affaires (MAD) | B5: ='104_Synthèse'!N7 -> 17652500 | C5: ='105_Synthèse'!N7 -> 0 | D5: ='106_Synthèse'!N7 -> 0 | G5: =SUM(B5:D5) -> 17652500 | H5: =Synthèse!O7+Synthèse!O9 -> 12803957 | I5: =+G5-H5 -> 4848543.1 | J5: =+I5/H5 -> 0.37867537
A6: Intrants | B6: =+'104_Synthèse'!N18 -> 3255984 | C6: =+'105_Synthèse'!N18 -> 0 | D6: =+'106_Synthèse'!N18 -> 94.8 | G6: =SUM(B6:D6) -> 3256078.8 | H6: =+Synthèse!O18 -> 5773682.9 | I6: =+G6-H6 -> -2517604.1 | J6: =+I6/H6 -> -0.43604821
A7: à l'hectare | B7: =B6/$B$2 -> #DIV/0! | C7: =C6/$C$2 -> #DIV/0! | D7: =D6/$D$2 -> 17.004484 | G7: =G6/$G$2 -> 584050.01 | H7: =H6/$H$2 -> 333738.9 | I7: =+G7-H7 -> 250311.11 | J7: =+I7/H7 -> 0.75002079
A8: Main d'œuvre directe | B8: ='104_Synthèse'!N25 -> 2548032.9 | C8: ='105_Synthèse'!N25 -> 0 | D8: ='106_Synthèse'!N25 -> 705.88235 | G8: =SUM(B8:D8) -> 2548738.8 | H8: =Synthèse!O25 -> 3967234.3 | I8: =+G8-H8 -> -1418495.5 | J8: =+I8/H8 -> -0.35755275
A9: à l'hectare | B9: =B8/$B$2 -> #DIV/0! | C9: =C8/$C$2 -> #DIV/0! | D9: =D8/$D$2 -> 126.61567 | G9: =G8/$G$2 -> 457172.87 | H9: =H8/$H$2 -> 229319.9 | I9: =+G9-H9 -> 227852.97 | J9: =+I9/H9 -> 0.99360312
A10: Energie | B10: ='104_Synthèse'!N21 -> 0 | C10: ='105_Synthèse'!N21 -> #DIV/0! | D10: ='106_Synthèse'!N21 -> 0 | G10: =SUM(B10:D10) -> #DIV/0! | H10: =Synthèse!O21 -> 298133.26 | I10: =+G10-H10 -> #DIV/0! | J10: =+I10/H10 -> #DIV/0!
A11: à l'hectare | B11: =B10/$B$2 -> #DIV/0! | C11: =C10/$C$2 -> #DIV/0! | D11: =D10/$D$2 -> 0 | G11: =G10/$G$2 -> #DIV/0! | H11: =H10/$H$2 -> 17233.136 | I11: =+G11-H11 -> #DIV/0! | J11: =+I11/H11 -> #DIV/0!
A12: Transport sur ventes | B12: ='104_Synthèse'!N28 -> 1.3239375e+08 | C12: ='105_Synthèse'!N28 -> 0 | D12: ='106_Synthèse'!N28 -> 0 | G12: =SUM(B12:D12) -> 1.3239375e+08 | H12: =Synthèse!O28 -> 142933 | I12: =+G12-H12 -> 1.3225082e+08 | J12: =+I12/H12 -> 925.2644
A13: à l'hectare | B13: =B12/$B$2 -> #DIV/0! | C13: =C12/$C$2 -> #DIV/0! | D13: =D12/$D$2 -> 0 | G13: =G12/$G$2 -> 23747758 | H13: =H12/$H$2 -> 8262.0231 | I13: =+G13-H13 -> 23739496 | J13: =+I13/H13 -> 2873.3272
A14: Charges variables (MAD) | B14: =+B12+B10+B8+B6 -> 1.3819777e+08 | C14: =+C12+C10+C8+C6 -> #DIV/0! | D14: =+D12+D10+D8+D6 -> 800.68235 | G14: =SUM(B14:D14) -> #DIV/0! | H14: =+H12+H10+H8+H6 -> 10181983 | I14: =+G14-H14 -> #DIV/0! | J14: =+I14/H14 -> #DIV/0!
A15: à l'hectare | B15: =B14/$B$2 -> #DIV/0! | C15: =C14/$C$2 -> #DIV/0! | D15: =D14/$D$2 -> 143.62015 | G15: =G14/$G$2 -> #DIV/0! | H15: =H14/$H$2 -> 588553.96 | I15: =+G15-H15 -> #DIV/0! | J15: =+I15/H15 -> #DIV/0!
A16: Main d'œuvre Adm. & Tech | B16: =+'104_Synthèse'!N26+'104_Synthèse'!N27 -> 364794.45 | C16: =+'105_Synthèse'!N26+'105_Synthèse'!N27 -> 423805.32 | D16: =+'106_Synthèse'!N26+'106_Synthèse'!N27 -> 139480.23 | G16: =SUM(B16:D16) -> 928080 | H16: =+Synthèse!O26+Synthèse!O27 -> 1212671.6 | I16: =+G16-H16 -> -284591.61 | J16: =+I16/H16 -> -0.23468152
A17: à l'hectare | B17: =B16/$B$2 -> #DIV/0! | C17: =C16/$C$2 -> #DIV/0! | D17: =D16/$D$2 -> 25018.876 | G17: =G16/$G$2 -> 166471.75 | H17: =H16/$H$2 -> 70096.625 | I17: =+G17-H17 -> 96375.124 | J17: =+I17/H17 -> 1.3748896
A18: Loyers fermes | B18: ='104_Synthèse'!N23 -> 451470.59 | C18: ='105_Synthèse'!N23 -> 0 | D18: ='106_Synthèse'!N23 -> 0 | G18: =SUM(B18:D18) -> 451470.59 | H18: =Synthèse!O23 -> 625000 | I18: =+G18-H18 -> -173529.41 | J18: =+I18/H18 -> -0.27764706
A19: à l'hectare | B19: =B18/$B$2 -> #DIV/0! | C19: =C18/$C$2 -> #DIV/0! | D19: =D18/$D$2 -> 0 | G19: =G18/$G$2 -> 80981.271 | H19: =H18/$H$2 -> 36127.168 | I19: =+G19-H19 -> 44854.104 | J19: =+I19/H19 -> 1.2415616
A20: Entretien & maintenance | B20: =+'104_Synthèse'!N24 -> 125618.64 | C20: =+'105_Synthèse'!N24 -> 17535.26 | D20: =+'106_Synthèse'!N24 -> 5771.0983 | G20: =SUM(B20:D20) -> 148925 | H20: =+Synthèse!O24 -> 308852.95 | I20: =+G20-H20 -> -159927.95 | J20: =+I20/H20 -> -0.5178126
A21: à l'hectare | B21: =B20/$B$2 -> #DIV/0! | C21: =C20/$C$2 -> #DIV/0! | D21: =D20/$D$2 -> 1035.1746 | G21: =G20/$G$2 -> 26713.004 | H21: =H20/$H$2 -> 17852.771 | I21: =+G21-H21 -> 8860.233 | J21: =+I21/H21 -> 0.49629454
A22: Autres Frais Généraux | B22: ='104_Synthèse'!N29+'104_Synthèse'!N22 -> 184979.19 | C22: =+'105_Synthèse'!N29+'105_Synthèse'!N22 -> 143569.94 | D22: =+'106_Synthèse'!N22+'106_Synthèse'!N29 -> 47250.867 | G22: =SUM(B22:D22) -> 375800 | H22: =+Synthèse!O29+Synthèse!O22 -> 253848.78 | I22: =+G22-H22 -> 121951.22 | J22: =+I22/H22 -> 0.48040891
A23: à l'hectare | B23: =B22/$B$2 -> #DIV/0! | C23: =C22/$C$2 -> #DIV/0! | D23: =D22/$D$2 -> 8475.4918 | G23: =G22/$G$2 -> 67408.072 | H23: =H22/$H$2 -> 14673.34 | I23: =+G23-H23 -> 52734.732 | J23: =+I23/H23 -> 3.5939146
A24: Charges fixes (MAD) | B24: =+B22+B20+B18+B16 -> 1126862.9 | C24: =+C22+C20+C18+C16 -> 584910.52 | D24: =+D22+D20+D18+D16 -> 192502.2 | G24: =SUM(B24:D24) -> 1904275.6 | H24: =+H22+H20+H18+H16 -> 2400373.3 | I24: =+G24-H24 -> -496097.76 | J24: =+I24/H24 -> -0.20667525
A25: à l'hectare | B25: =B24/$B$2 -> #DIV/0! | C25: =C24/$C$2 -> #DIV/0! | D25: =D24/$D$2 -> 34529.542 | G25: =G24/$G$2 -> 341574.1 | H25: =H24/$H$2 -> 138749.9 | I25: =+G25-H25 -> 202824.19 | J25: =+I25/H25 -> 1.461797
A26: EBITDA (MAD) | B26: =+B5-B14-B24 -> -1.2167213e+08 | C26: =+C5-C14-C24 -> #DIV/0! | D26: =+D5-D14-D24 -> -193302.88 | G26: =SUM(B26:D26) -> #DIV/0! | H26: =+H5-H14-H24 -> 221600.11 | I26: =+G26-H26 -> #DIV/0! | J26: =+I26/H26 -> #DIV/0!
A27: à l'hectare | B27: =B26/$B$2 -> #DIV/0! | C27: =C26/$C$2 -> #DIV/0! | D27: =D26/$D$2 -> -34673.162 | G27: =G26/$G$2 -> #DIV/0! | H27: =H26/$H$2 -> 12809.255 | I27: =+G27-H27 -> #DIV/0! | J27: =+I27/H27 -> #DIV/0!
A28: En % du chiffre d'affaires | B28: =B26/$B$5 -> -6.8926288 | C28: =C26/$C$5 -> #DIV/0! | D28: =D26/$D$5 -> #DIV/0! | G28: =G26/$G$5 -> #DIV/0! | H28: =H26/$H$5 -> 0.017307158 | I28: =+G28-H28 -> #DIV/0!
A29: Amortissements | B29: ='104_Synthèse'!N32 -> 1019827.7 | C29: ='105_Synthèse'!N32 -> 1580439.4 | D29: ='106_Synthèse'!N32 -> 292852.23 | G29: =SUM(B29:D29) -> 2893119.4 | H29: =Synthèse!O32 -> 2724261.2 | I29: =+G29-H29 -> 168858.2 | J29: =+I29/H29 -> 0.061983115
A30: à l'hectare | B30: =B29/$B$2 -> #DIV/0! | C30: =C29/$C$2 -> #DIV/0! | D30: =D29/$D$2 -> 52529.549 | G30: =G29/$G$2 -> 518945.18 | H30: =H29/$H$2 -> 157471.75 | I30: =+G30-H30 -> 361473.44 | J30: =+I30/H30 -> 2.2954812
A31: Résultat d'exploitation | B31: =+B26-B29 -> -1.2269196e+08 | C31: =+C26-C29 -> #DIV/0! | D31: =+D26-D29 -> -486155.11 | G31: =SUM(B31:D31) -> #DIV/0! | H31: =+H26-H29 -> -2502661.1 | I31: =+G31-H31 -> #DIV/0! | J31: =+I31/H31 -> #DIV/0!
A32: En % du chiffre d'affaires | B32: =B31/$B$5 -> -6.9504012 | C32: =C31/$B$5 -> #DIV/0! | D32: =D31/$B$5 -> -0.027540298 | G32: =G31/$B$5 -> #DIV/0! | H32: =H31/$B$5 -> -0.14177375 | I32: =+G32-H32 -> #DIV/0!
A35: Ceck centralisation | G35: =G31-Synthèse!N33 -> #DIV/0! | H35: =H31-Synthèse!O33 -> 0

Sheet Synthèse
B1: BUD | C1: BUD | D1: BUD | E1: BUD | F1: BUD | G1: BUD | H1: BUD | I1: BUD | J1: BUD | K1: BUD | L1: BUD | M1: BUD | N1: BUD | O1: REEL | P1: VARIATION | Q1: VARIATION
A2: Analyse totale (MAD) | B2: 45839 | C2: =+B2+31 -> 45870 | D2: =+C2+31 -> 45901 | E2: =+D2+31 -> 45932 | F2: =+E2+31 -> 45963 | G2: =+F2+31 -> 45994 | H2: =+G2+31 -> 46025 | I2: =+H2+31 -> 46056 | J2: =+I2+31 -> 46087 | ... M2: =+L2+31 -> 46180 | N2: 25/26 | O2: 18/19 | P2: BUD-REEL | Q2: % | R2: source | S2: check
A3: Sup Tot (ha) | B3: =+'104_Synthèse'!B3+'105_Synthèse'!B3+'106_Synthèse'!B3 -> 5.575 | C3: =+'104_Synthèse'!C3+'105_Synthèse'!C3+'106_Synthèse'!C3 -> 5.575 | D3: =+'104_Synthèse'!D3+'105_Synthèse'!D3+'106_Synthèse'!D3 -> 5.575 | E3: =+'104_Synthèse'!E3+'105_Synthèse'!E3+'106_Synthèse'!E3 -> 5.575 | F3: =+'104_Synthèse'!F3+'105_Synthèse'!F3+'106_Synthèse'!F3 -> 5.575 | G3: =+'104_Synthèse'!G3+'105_Synthèse'!G3+'106_Synthèse'!G3 -> 5.575 | H3: =+'104_Synthèse'!H3+'105_Synthèse'!H3+'106_Synthèse'!H3 -> 5.575 | I3: =+'104_Synthèse'!I3+'105_Synthèse'!I3+'106_Synthèse'!I3 -> 5.575 | ... M3: =+'104_Synthèse'!M3+'105_Synthèse'!M3+'106_Synthèse'!M3 -> 5.575 | N3: =+'106_Synthèse'!N3+'104_Synthèse'!N3+'105_Synthèse'!N3 -> 5.575 | O3: =+'104_Synthèse'!O3+'105_Synthèse'!O3++'106_Synthèse'!O3 -> 17.3 | P3: =+N3-O3 -> -11.725 | Q3: =+P3/O3 -> -0.67774566 | R3: =+'Plan de culture 104 '!B3+'Plan de culture 105'!B3+'Plan de culture 106'!C3 -> 5.575 | S3: =+N3-R3 -> 0
A4: Sup productive | B4: =+'104_Synthèse'!B4+'105_Synthèse'!B4+'106_Synthèse'!B4 -> 26.14 | C4: =+'104_Synthèse'!C4+'105_Synthèse'!C4+'106_Synthèse'!C4 -> 26.14 | D4: =+'104_Synthèse'!D4+'105_Synthèse'!D4+'106_Synthèse'!D4 -> 26.14 | E4: =+'104_Synthèse'!E4+'105_Synthèse'!E4+'106_Synthèse'!E4 -> 26.14 | F4: =+'104_Synthèse'!F4+'105_Synthèse'!F4+'106_Synthèse'!F4 -> 26.14 | G4: =+'104_Synthèse'!G4+'105_Synthèse'!G4+'106_Synthèse'!G4 -> 26.14 | H4: =+'104_Synthèse'!H4+'105_Synthèse'!H4+'106_Synthèse'!H4 -> 26.14 | I4: =+'104_Synthèse'!I4+'105_Synthèse'!I4+'106_Synthèse'!I4 -> 26.14 | ... M4: =+'104_Synthèse'!M4+'105_Synthèse'!M4+'106_Synthèse'!M4 -> 26.14 | N4: =+'106_Synthèse'!N4+'104_Synthèse'!N4+'105_Synthèse'!N4 -> 26.14 | O4: =+'104_Synthèse'!O4+'105_Synthèse'!O4++'106_Synthèse'!O4 -> 17.3 | P4: =+N4-O4 -> 8.84 | Q4: =+P4/O4 -> 0.51098266 | R4: ='106_Synthèse'!N4+'104_Synthèse'!N4+'105_Synthèse'!N4 -> 26.14 | S4: =+N4-R4 -> 0
A5: Vol (kg) | B5: =+'104_Synthèse'!B5+'105_Synthèse'!B5+'106_Synthèse'!B5 -> 0 | C5: =+'104_Synthèse'!C5+'105_Synthèse'!C5+'106_Synthèse'!C5 -> 0 | D5: =+'104_Synthèse'!D5+'105_Synthèse'!D5+'106_Synthèse'!D5 -> 0 | E5: =+'104_Synthèse'!E5+'105_Synthèse'!E5+'106_Synthèse'!E5 -> 1.080386e+08 | F5: =+'104_Synthèse'!F5+'105_Synthèse'!F5+'106_Synthèse'!F5 -> 1.083456e+08 | G5: =+'104_Synthèse'!G5+'105_Synthèse'!G5+'106_Synthèse'!G5 -> 81259200 | H5: =+'104_Synthèse'!H5+'105_Synthèse'!H5+'106_Synthèse'!H5 -> 81259200 | I5: =+'104_Synthèse'!I5+'105_Synthèse'!I5+'106_Synthèse'!I5 -> 1.083456e+08 | ... M5: =+'104_Synthèse'!M5+'105_Synthèse'!M5+'106_Synthèse'!M5 -> 27086400 | N5: =SUM(B5:M5) -> 731025800 | O5: =+'104_Synthèse'!O5+'105_Synthèse'!O5++'106_Synthèse'!O5 -> 1982993.5 | P5: =+N5-O5 -> 7.2904281e+08 | Q5: =+P5/O5 -> 367.6476 | R5: ='106_Synthèse'!N5+'104_Synthèse'!N5+'105_Synthèse'!N5 -> 731025800 | S5: =+N5-R5 -> 0
A6: rendement (t/ha) | B6: =+B5/B4/1000 -> 0 | C6: =+C5/C4/1000 -> 0 | D6: =+D5/D4/1000 -> 0 | E6: =+E5/E4/1000 -> 4133.0757 | F6: =+F5/F4/1000 -> 4144.8202 | G6: =+G5/G4/1000 -> 3108.6151 | H6: =+H5/H4/1000 -> 3108.6151 | I6: =+I5/I4/1000 -> 4144.8202 | ... O6: =+O5/O4/1000 -> 114.6239 | P6: =+N6-O6 -> 27851.168 | Q6: =+P6/O6 -> 242.97871 | R6: =+R5/R4/1000 -> 27965.792 | S6: =+N6-R6 -> 0
A7: CA EXPORT(MAD) | B7: =+'104_Synthèse'!B7+'105_Synthèse'!B7+'106_Synthèse'!B7 -> 0 | C7: =+'104_Synthèse'!C7+'105_Synthèse'!C7+'106_Synthèse'!C7 -> 0 | D7: =+'104_Synthèse'!D7+'105_Synthèse'!D7+'106_Synthèse'!D7 -> 0 | E7: =+'104_Synthèse'!E7+'105_Synthèse'!E7+'106_Synthèse'!E7 -> 0 | F7: =+'104_Synthèse'!F7+'105_Synthèse'!F7+'106_Synthèse'!F7 -> 3070000 | G7: =+'104_Synthèse'!G7+'105_Synthèse'!G7+'106_Synthèse'!G7 -> 2302500 | H7: =+'104_Synthèse'!H7+'105_Synthèse'!H7+'106_Synthèse'!H7 -> 2302500 | I7: =+'104_Synthèse'!I7+'105_Synthèse'!I7+'106_Synthèse'!I7 -> 3070000 | ... M7: =+'104_Synthèse'!M7+'105_Synthèse'!M7+'106_Synthèse'!M7 -> 767500 | N7: =SUM(B7:M7) -> 17652500 | O7: =+'104_Synthèse'!O7+'105_Synthèse'!O7++'106_Synthèse'!O7 -> 11264311 | P7: =+N7-O7 -> 6388189.1 | Q7: =+P7/O7 -> 0.56711761 | R7: ='106_Synthèse'!N7+'104_Synthèse'!N7+'105_Synthèse'!N7 -> 17652500 | S7: =+N7-R7 -> 0
A8: CA MARCHE LOCAL(MAD)
A9: Autres revenus (MAD) | B9: =+'104_Synthèse'!B9+'105_Synthèse'!B9+'106_Synthèse'!B9 -> 0 | C9: =+'104_Synthèse'!C9+'105_Synthèse'!C9+'106_Synthèse'!C9 -> 0 | D9: =+'104_Synthèse'!D9+'105_Synthèse'!D9+'106_Synthèse'!D9 -> 0 | E9: =+'104_Synthèse'!E9+'105_Synthèse'!E9+'106_Synthèse'!E9 -> 0 | F9: =+'104_Synthèse'!F9+'105_Synthèse'!F9+'106_Synthèse'!F9 -> 0 | G9: =+'104_Synthèse'!G9+'105_Synthèse'!G9+'106_Synthèse'!G9 -> 0 | H9: =+'104_Synthèse'!H9+'105_Synthèse'!H9+'106_Synthèse'!H9 -> 0 | I9: =+'104_Synthèse'!I9+'105_Synthèse'!I9+'106_Synthèse'!I9 -> 0 | ... M9: =+'104_Synthèse'!M9+'105_Synthèse'!M9+'106_Synthèse'!M9 -> 0 | N9: =SUM(B9:M9) -> 0 | O9: =+'104_Synthèse'!O9+'105_Synthèse'!O9++'106_Synthèse'!O9 -> 1539646 | P9: =+N9-O9 -> -1539646 | Q9: =+P9/O9 -> -1 | R9: ='106_Synthèse'!N9+'104_Synthèse'!N9+'105_Synthèse'!N9 -> 0 | S9: =+N9-R9 -> 0
A10: Production encours (MAD) | B10: =+'104_Synthèse'!B10+'105_Synthèse'!B10+'106_Synthèse'!B10 -> #DIV/0! | C10: =+'104_Synthèse'!C10+'105_Synthèse'!C10+'106_Synthèse'!C10 -> #DIV/0! | D10: =+'104_Synthèse'!D10+'105_Synthèse'!D10+'106_Synthèse'!D10 -> #DIV/0! | E10: =+'104_Synthèse'!E10+'105_Synthèse'!E10+'106_Synthèse'!E10 -> #DIV/0! | F10: =+'104_Synthèse'!F10+'105_Synthèse'!F10+'106_Synthèse'!F10 -> #DIV/0! | G10: =+'104_Synthèse'!G10+'105_Synthèse'!G10+'106_Synthèse'!G10 -> #DIV/0! | H10: =+'104_Synthèse'!H10+'105_Synthèse'!H10+'106_Synthèse'!H10 -> #DIV/0! | I10: =+'104_Synthèse'!I10+'105_Synthèse'!I10+'106_Synthèse'!I10 -> #DIV/0! | ... M10: =+'104_Synthèse'!M10+'105_Synthèse'!M10+'106_Synthèse'!M10 -> #DIV/0! | N10: =SUM(B10:M10) -> #DIV/0! | O10: =+'104_Synthèse'!O10+'105_Synthèse'!O10++'106_Synthèse'!O10 -> 0 | P10: =+N10-O10 -> #DIV/0! | Q10: =+P10/O10 -> #DIV/0! | R10: ='106_Synthèse'!N10+'104_Synthèse'!N10+'105_Synthèse'!N10 -> #DIV/0! | S10: =+N10-R10 -> #DIV/0!
A11: Production totale (MAD) | B11: =+B10+B7+B9 -> #DIV/0! | C11: =+C10+C7+C9 -> #DIV/0! | D11: =+D10+D7+D9 -> #DIV/0! | E11: =+E10+E7+E9 -> #DIV/0! | F11: =+F10+F7+F9 -> #DIV/0! | G11: =+G10+G7+G9 -> #DIV/0! | H11: =+H10+H7+H9 -> #DIV/0! | I11: =+I10+I7+I9 -> #DIV/0! | ... M11: =+M10+M7+M9 -> #DIV/0! | N11: =SUM(B11:M11) -> #DIV/0! | O11: =+O10+O7+O9 -> 12803957 | P11: =+N11-O11 -> #DIV/0! | Q11: =+P11/O11 -> #DIV/0! | R11: ='106_Synthèse'!N11+'104_Synthèse'!N11+'105_Synthèse'!N11 -> #DIV/0! | S11: =+N11-R11 -> #DIV/0!
A12: Consommation Semences | B12: =+'104_Synthèse'!B12+'105_Synthèse'!B12+'106_Synthèse'!B12 -> 3.2 | C12: =+'104_Synthèse'!C12+'105_Synthèse'!C12+'106_Synthèse'!C12 -> 1494603.2 | D12: =+'104_Synthèse'!D12+'105_Synthèse'!D12+'106_Synthèse'!D12 -> 3.2 | E12: =+'104_Synthèse'!E12+'105_Synthèse'!E12+'106_Synthèse'!E12 -> 3.2 | F12: =+'104_Synthèse'!F12+'105_Synthèse'!F12+'106_Synthèse'!F12 -> 3.2 | G12: =+'104_Synthèse'!G12+'105_Synthèse'!G12+'106_Synthèse'!G12 -> 3.2 | H12: =+'104_Synthèse'!H12+'105_Synthèse'!H12+'106_Synthèse'!H12 -> 3.2 | I12: =+'104_Synthèse'!I12+'105_Synthèse'!I12+'106_Synthèse'!I12 -> 3.2 | ... M12: =+'104_Synthèse'!M12+'105_Synthèse'!M12+'106_Synthèse'!M12 -> 3.2 | N12: =SUM(B12:M12) -> 1494638.4 | O12: =+'104_Synthèse'!O12+'105_Synthèse'!O12++'106_Synthèse'!O12 -> 1487208.2 | P12: =+N12-O12 -> 7430.15 | Q12: =+P12/O12 -> 0.0049960387 | R12: ='106_Synthèse'!N12+'104_Synthèse'!N12+'105_Synthèse'!N12 -> 1494638.4 | S12: =+N12-R12 -> 0
A13: Consommation Engrais | B13: =+'104_Synthèse'!B13+'105_Synthèse'!B13+'106_Synthèse'!B13 -> 0 | C13: =+'104_Synthèse'!C13+'105_Synthèse'!C13+'106_Synthèse'!C13 -> 0 | D13: =+'104_Synthèse'!D13+'105_Synthèse'!D13+'106_Synthèse'!D13 -> 0 | E13: =+'104_Synthèse'!E13+'105_Synthèse'!E13+'106_Synthèse'!E13 -> 0 | F13: =+'104_Synthèse'!F13+'105_Synthèse'!F13+'106_Synthèse'!F13 -> 0 | G13: =+'104_Synthèse'!G13+'105_Synthèse'!G13+'106_Synthèse'!G13 -> 0 | H13: =+'104_Synthèse'!H13+'105_Synthèse'!H13+'106_Synthèse'!H13 -> 0 | I13: =+'104_Synthèse'!I13+'105_Synthèse'!I13+'106_Synthèse'!I13 -> 0 | ... M13: =+'104_Synthèse'!M13+'105_Synthèse'!M13+'106_Synthèse'!M13 -> 0 | N13: =SUM(B13:M13) -> 0 | O13: =+'104_Synthèse'!O13+'105_Synthèse'!O13++'106_Synthèse'!O13 -> 1893892.2 | P13: =+N13-O13 -> -1893892.2 | Q13: =+P13/O13 -> -1 | R13: ='106_Synthèse'!N13+'104_Synthèse'!N13+'105_Synthèse'!N13 -> 0 | S13: =+N13-R13 -> 0
A14: Consommation Plants | B14: =+'104_Synthèse'!B14+'105_Synthèse'!B14+'106_Synthèse'!B14 -> 0 | C14: =+'104_Synthèse'!C14+'105_Synthèse'!C14+'106_Synthèse'!C14 -> 1113000 | D14: =+'104_Synthèse'!D14+'105_Synthèse'!D14+'106_Synthèse'!D14 -> 0 | E14: =+'104_Synthèse'!E14+'105_Synthèse'!E14+'106_Synthèse'!E14 -> 0 | F14: =+'104_Synthèse'!F14+'105_Synthèse'!F14+'106_Synthèse'!F14 -> 0 | G14: =+'104_Synthèse'!G14+'105_Synthèse'!G14+'106_Synthèse'!G14 -> 0 | H14: =+'104_Synthèse'!H14+'105_Synthèse'!H14+'106_Synthèse'!H14 -> 0 | I14: =+'104_Synthèse'!I14+'105_Synthèse'!I14+'106_Synthèse'!I14 -> 0 | ... M14: =+'104_Synthèse'!M14+'105_Synthèse'!M14+'106_Synthèse'!M14 -> 0 | N14: =SUM(B14:M14) -> 1113000 | O14: =+'104_Synthèse'!O14+'105_Synthèse'!O14++'106_Synthèse'!O14 -> 670159.2 | P14: =+N14-O14 -> 442840.8 | Q14: =+P14/O14 -> 0.6607994 | R14: ='106_Synthèse'!N14+'104_Synthèse'!N14+'105_Synthèse'!N14 -> 1113000 | S14: =+N14-R14 -> 0
A15: Consommation Phytos | B15: =+'104_Synthèse'!B15+'105_Synthèse'!B15+'106_Synthèse'!B15 -> 0 | C15: =+'104_Synthèse'!C15+'105_Synthèse'!C15+'106_Synthèse'!C15 -> 0 | D15: =+'104_Synthèse'!D15+'105_Synthèse'!D15+'106_Synthèse'!D15 -> 0 | E15: =+'104_Synthèse'!E15+'105_Synthèse'!E15+'106_Synthèse'!E15 -> 0 | F15: =+'104_Synthèse'!F15+'105_Synthèse'!F15+'106_Synthèse'!F15 -> 0 | G15: =+'104_Synthèse'!G15+'105_Synthèse'!G15+'106_Synthèse'!G15 -> 0 | H15: =+'104_Synthèse'!H15+'105_Synthèse'!H15+'106_Synthèse'!H15 -> 0 | I15: =+'104_Synthèse'!I15+'105_Synthèse'!I15+'106_Synthèse'!I15 -> 0 | ... M15: =+'104_Synthèse'!M15+'105_Synthèse'!M15+'106_Synthèse'!M15 -> 0 | N15: =SUM(B15:M15) -> 0 | O15: =+'104_Synthèse'!O15+'105_Synthèse'!O15++'106_Synthèse'!O15 -> 1272725.3 | P15: =+N15-O15 -> -1272725.3 | Q15: =+P15/O15 -> -1 | R15: ='106_Synthèse'!N15+'104_Synthèse'!N15+'105_Synthèse'!N15 -> 0 | S15: =+N15-R15 -> 0
A16: Consommation Insectes | B16: =+'104_Synthèse'!B16+'105_Synthèse'!B16+'106_Synthèse'!B16 -> 4.7 | C16: =+'104_Synthèse'!C16+'105_Synthèse'!C16+'106_Synthèse'!C16 -> 4.7 | D16: =+'104_Synthèse'!D16+'105_Synthèse'!D16+'106_Synthèse'!D16 -> 4.7 | E16: =+'104_Synthèse'!E16+'105_Synthèse'!E16+'106_Synthèse'!E16 -> 4.7 | F16: =+'104_Synthèse'!F16+'105_Synthèse'!F16+'106_Synthèse'!F16 -> 4.7 | G16: =+'104_Synthèse'!G16+'105_Synthèse'!G16+'106_Synthèse'!G16 -> 4.7 | H16: =+'104_Synthèse'!H16+'105_Synthèse'!H16+'106_Synthèse'!H16 -> 4.7 | I16: =+'104_Synthèse'!I16+'105_Synthèse'!I16+'106_Synthèse'!I16 -> 4.7 | ... M16: =+'104_Synthèse'!M16+'105_Synthèse'!M16+'106_Synthèse'!M16 -> 4.7 | N16: =SUM(B16:M16) -> 56.4 | O16: =+'104_Synthèse'!O16+'105_Synthèse'!O16++'106_Synthèse'!O16 -> 307765.01 | P16: =+N16-O16 -> -307708.61 | Q16: =+P16/O16 -> -0.99981674 | R16: ='106_Synthèse'!N16+'104_Synthèse'!N16+'105_Synthèse'!N16 -> 56.4 | S16: =+N16-R16 -> 0
A17: Autres fournitures agricoles | B17: =+'104_Synthèse'!B17+'105_Synthèse'!B17+'106_Synthèse'!B17 -> 479534 | C17: =+'104_Synthèse'!C17+'105_Synthèse'!C17+'106_Synthèse'!C17 -> 15350 | D17: =+'104_Synthèse'!D17+'105_Synthèse'!D17+'106_Synthèse'!D17 -> 15350 | E17: =+'104_Synthèse'!E17+'105_Synthèse'!E17+'106_Synthèse'!E17 -> 15350 | F17: =+'104_Synthèse'!F17+'105_Synthèse'!F17+'106_Synthèse'!F17 -> 15350 | G17: =+'104_Synthèse'!G17+'105_Synthèse'!G17+'106_Synthèse'!G17 -> 15350 | H17: =+'104_Synthèse'!H17+'105_Synthèse'!H17+'106_Synthèse'!H17 -> 15350 | I17: =+'104_Synthèse'!I17+'105_Synthèse'!I17+'106_Synthèse'!I17 -> 15350 | ... M17: =+'104_Synthèse'!M17+'105_Synthèse'!M17+'106_Synthèse'!M17 -> 15350 | N17: =SUM(B17:M17) -> 648384 | O17: =+'104_Synthèse'!O17+'105_Synthèse'!O17++'106_Synthèse'!O17 -> 141932.94 | P17: =+N17-O17 -> 506451.06 | Q17: =+P17/O17 -> 3.5682418 | R17: ='106_Synthèse'!N17+'104_Synthèse'!N17+'105_Synthèse'!N17 -> 648384 | S17: =+N17-R17 -> 0
A18: Total consommation Intrants | B18: =SUM(B12:B17) -> 479541.9 | C18: =SUM(C12:C17) -> 2622957.9 | D18: =SUM(D12:D17) -> 15357.9 | E18: =SUM(E12:E17) -> 15357.9 | F18: =SUM(F12:F17) -> 15357.9 | G18: =SUM(G12:G17) -> 15357.9 | H18: =SUM(H12:H17) -> 15357.9 | I18: =SUM(I12:I17) -> 15357.9 | ... M18: =SUM(M12:M17) -> 15357.9 | N18: =SUM(B18:M18) -> 3256078.8 | O18: =SUM(O12:O17) -> 5773682.9 | P18: =+N18-O18 -> -2517604.1 | Q18: =+P18/O18 -> -0.43604821 | R18: ='106_Synthèse'!N18+'104_Synthèse'!N18+'105_Synthèse'!N18 -> 3256078.8 | S18: =+N18-R18 -> 0
A19: Electricité | B19: =+'104_Synthèse'!B19+'105_Synthèse'!B19+'106_Synthèse'!B19 -> 0 | C19: =+'104_Synthèse'!C19+'105_Synthèse'!C19+'106_Synthèse'!C19 -> 0 | D19: =+'104_Synthèse'!D19+'105_Synthèse'!D19+'106_Synthèse'!D19 -> 0 | E19: =+'104_Synthèse'!E19+'105_Synthèse'!E19+'106_Synthèse'!E19 -> 0 | F19: =+'104_Synthèse'!F19+'105_Synthèse'!F19+'106_Synthèse'!F19 -> 0 | G19: =+'104_Synthèse'!G19+'105_Synthèse'!G19+'106_Synthèse'!G19 -> 0 | H19: =+'104_Synthèse'!H19+'105_Synthèse'!H19+'106_Synthèse'!H19 -> 0 | I19: =+'104_Synthèse'!I19+'105_Synthèse'!I19+'106_Synthèse'!I19 -> 0 | ... M19: =+'104_Synthèse'!M19+'105_Synthèse'!M19+'106_Synthèse'!M19 -> 0 | N19: =SUM(B19:M19) -> 0 | O19: =+'104_Synthèse'!O19+'105_Synthèse'!O19++'106_Synthèse'!O19 -> 250614.88 | P19: =+N19-O19 -> -250614.88 | Q19: =+P19/O19 -> -1 | R19: ='106_Synthèse'!N19+'104_Synthèse'!N19+'105_Synthèse'!N19 -> 0 | S19: =+N19-R19 -> 0
A20: Eau | B20: =+'104_Synthèse'!B20+'105_Synthèse'!B20+'106_Synthèse'!B20 -> #DIV/0! | C20: =+'104_Synthèse'!C20+'105_Synthèse'!C20+'106_Synthèse'!C20 -> #DIV/0! | D20: =+'104_Synthèse'!D20+'105_Synthèse'!D20+'106_Synthèse'!D20 -> #DIV/0! | E20: =+'104_Synthèse'!E20+'105_Synthèse'!E20+'106_Synthèse'!E20 -> #DIV/0! | F20: =+'104_Synthèse'!F20+'105_Synthèse'!F20+'106_Synthèse'!F20 -> #DIV/0! | G20: =+'104_Synthèse'!G20+'105_Synthèse'!G20+'106_Synthèse'!G20 -> #DIV/0! | H20: =+'104_Synthèse'!H20+'105_Synthèse'!H20+'106_Synthèse'!H20 -> #DIV/0! | I20: =+'104_Synthèse'!I20+'105_Synthèse'!I20+'106_Synthèse'!I20 -> #DIV/0! | ... M20: =+'104_Synthèse'!M20+'105_Synthèse'!M20+'106_Synthèse'!M20 -> #DIV/0! | N20: =SUM(B20:M20) -> #DIV/0! | O20: =+'104_Synthèse'!O20+'105_Synthèse'!O20++'106_Synthèse'!O20 -> 47518.377 | P20: =+N20-O20 -> #DIV/0! | Q20: =+P20/O20 -> #DIV/0! | R20: ='106_Synthèse'!N20+'104_Synthèse'!N20+'105_Synthèse'!N20 -> #DIV/0! | S20: =+N20-R20 -> #DIV/0!
A21: Total consommation Energie | B21: =SUM(B19:B20) -> #DIV/0! | C21: =SUM(C19:C20) -> #DIV/0! | D21: =SUM(D19:D20) -> #DIV/0! | E21: =SUM(E19:E20) -> #DIV/0! | F21: =SUM(F19:F20) -> #DIV/0! | G21: =SUM(G19:G20) -> #DIV/0! | H21: =SUM(H19:H20) -> #DIV/0! | I21: =SUM(I19:I20) -> #DIV/0! | ... M21: =SUM(M19:M20) -> #DIV/0! | N21: =SUM(B21:M21) -> #DIV/0! | O21: =+O20+O19 -> 298133.26 | P21: =+N21-O21 -> #DIV/0! | Q21: =+P21/O21 -> #DIV/0! | R21: ='106_Synthèse'!N21+'104_Synthèse'!N21+'105_Synthèse'!N21 -> #DIV/0! | S21: =+N21-R21 -> #DIV/0!
A22: Prestations & analyses | B22: =+'104_Synthèse'!B22+'105_Synthèse'!B22+'106_Synthèse'!B22 -> 0 | C22: =+'104_Synthèse'!C22+'105_Synthèse'!C22+'106_Synthèse'!C22 -> 61400 | D22: =+'104_Synthèse'!D22+'105_Synthèse'!D22+'106_Synthèse'!D22 -> 0 | E22: =+'104_Synthèse'!E22+'105_Synthèse'!E22+'106_Synthèse'!E22 -> 0 | F22: =+'104_Synthèse'!F22+'105_Synthèse'!F22+'106_Synthèse'!F22 -> 0 | G22: =+'104_Synthèse'!G22+'105_Synthèse'!G22+'106_Synthèse'!G22 -> 0 | H22: =+'104_Synthèse'!H22+'105_Synthèse'!H22+'106_Synthèse'!H22 -> 0 | I22: =+'104_Synthèse'!I22+'105_Synthèse'!I22+'106_Synthèse'!I22 -> 0 | ... M22: =+'104_Synthèse'!M22+'105_Synthèse'!M22+'106_Synthèse'!M22 -> 0 | N22: =SUM(B22:M22) -> 61400 | O22: =+'104_Synthèse'!O22+'105_Synthèse'!O22++'106_Synthèse'!O22 -> 58498.533 | P22: =+N22-O22 -> 2901.4674 | Q22: =-+P22/O22 -> -0.049598978 | R22: ='106_Synthèse'!N22+'104_Synthèse'!N22+'105_Synthèse'!N22 -> 61400 | S22: =+N22-R22 -> 0
A23: Loyers fermes | B23: =+'104_Synthèse'!B23+'105_Synthèse'!B23+'106_Synthèse'!B23 -> 37622.549 | C23: =+'104_Synthèse'!C23+'105_Synthèse'!C23+'106_Synthèse'!C23 -> 37622.549 | D23: =+'104_Synthèse'!D23+'105_Synthèse'!D23+'106_Synthèse'!D23 -> 37622.549 | E23: =+'104_Synthèse'!E23+'105_Synthèse'!E23+'106_Synthèse'!E23 -> 37622.549 | F23: =+'104_Synthèse'!F23+'105_Synthèse'!F23+'106_Synthèse'!F23 -> 37622.549 | G23: =+'104_Synthèse'!G23+'105_Synthèse'!G23+'106_Synthèse'!G23 -> 37622.549 | H23: =+'104_Synthèse'!H23+'105_Synthèse'!H23+'106_Synthèse'!H23 -> 37622.549 | I23: =+'104_Synthèse'!I23+'105_Synthèse'!I23+'106_Synthèse'!I23 -> 37622.549 | ... M23: =+'104_Synthèse'!M23+'105_Synthèse'!M23+'106_Synthèse'!M23 -> 37622.549 | N23: =SUM(B23:M23) -> 451470.59 | O23: =+'104_Synthèse'!O23+'105_Synthèse'!O23++'106_Synthèse'!O23 -> 625000 | P23: =+N23-O23 -> -173529.41 | Q23: =+P23/O23 -> -0.27764706 | R23: ='106_Synthèse'!N23+'104_Synthèse'!N23+'105_Synthèse'!N23 -> 451470.59 | S23: =+N23-R23 -> 0
A24: Entretien | B24: =+'104_Synthèse'!B24+'105_Synthèse'!B24+'106_Synthèse'!B24 -> 12237.5 | C24: =+'104_Synthèse'!C24+'105_Synthèse'!C24+'106_Synthèse'!C24 -> 16075 | D24: =+'104_Synthèse'!D24+'105_Synthèse'!D24+'106_Synthèse'!D24 -> 16075 | E24: =+'104_Synthèse'!E24+'105_Synthèse'!E24+'106_Synthèse'!E24 -> 12237.5 | F24: =+'104_Synthèse'!F24+'105_Synthèse'!F24+'106_Synthèse'!F24 -> 12237.5 | G24: =+'104_Synthèse'!G24+'105_Synthèse'!G24+'106_Synthèse'!G24 -> 16075 | H24: =+'104_Synthèse'!H24+'105_Synthèse'!H24+'106_Synthèse'!H24 -> 16075 | I24: =+'104_Synthèse'!I24+'105_Synthèse'!I24+'106_Synthèse'!I24 -> 12237.5 | ... M24: =+'104_Synthèse'!M24+'105_Synthèse'!M24+'106_Synthèse'!M24 -> 3200 | N24: =SUM(B24:M24) -> 148925 | O24: =+'104_Synthèse'!O24+'105_Synthèse'!O24++'106_Synthèse'!O24 -> 308852.95 | P24: =+N24-O24 -> -159927.95 | Q24: =+P24/O24 -> -0.5178126 | R24: ='106_Synthèse'!N24+'104_Synthèse'!N24+'105_Synthèse'!N24 -> 148925 | S24: =+N24-R24 -> 0
A25: Main d'œuvre Directe | B25: =+'104_Synthèse'!B25+'105_Synthèse'!B25+'106_Synthèse'!B25 -> 354391.69 | C25: =+'104_Synthèse'!C25+'105_Synthèse'!C25+'106_Synthèse'!C25 -> 309277.47 | D25: =+'104_Synthèse'!D25+'105_Synthèse'!D25+'106_Synthèse'!D25 -> 278050.93 | E25: =+'104_Synthèse'!E25+'105_Synthèse'!E25+'106_Synthèse'!E25 -> 277413.75 | F25: =+'104_Synthèse'!F25+'105_Synthèse'!F25+'106_Synthèse'!F25 -> 271051.42 | G25: =+'104_Synthèse'!G25+'105_Synthèse'!G25+'106_Synthèse'!G25 -> 261371.35 | H25: =+'104_Synthèse'!H25+'105_Synthèse'!H25+'106_Synthèse'!H25 -> 259638.92 | I25: =+'104_Synthèse'!I25+'105_Synthèse'!I25+'106_Synthèse'!I25 -> 259783.08 | ... M25: =+'104_Synthèse'!M25+'105_Synthèse'!M25+'106_Synthèse'!M25 -> 6316.4706 | N25: =SUM(B25:M25) -> 2548738.8 | O25: =+'104_Synthèse'!O25+'105_Synthèse'!O25++'106_Synthèse'!O25 -> 3967234.3 | P25: =+N25-O25 -> -1418495.5 | Q25: =+P25/O25 -> -0.35755275 | R25: ='106_Synthèse'!N25+'104_Synthèse'!N25+'105_Synthèse'!N25 -> 2548738.8 | S25: =+N25-R25 -> 0
A26: Main d'œuvre Adm. | B26: =+'104_Synthèse'!B26+'105_Synthèse'!B26+'106_Synthèse'!B26 -> 77340 | C26: =+'104_Synthèse'!C26+'105_Synthèse'!C26+'106_Synthèse'!C26 -> 77340 | D26: =+'104_Synthèse'!D26+'105_Synthèse'!D26+'106_Synthèse'!D26 -> 77340 | E26: =+'104_Synthèse'!E26+'105_Synthèse'!E26+'106_Synthèse'!E26 -> 77340 | F26: =+'104_Synthèse'!F26+'105_Synthèse'!F26+'106_Synthèse'!F26 -> 77340 | G26: =+'104_Synthèse'!G26+'105_Synthèse'!G26+'106_Synthèse'!G26 -> 77340 | H26: =+'104_Synthèse'!H26+'105_Synthèse'!H26+'106_Synthèse'!H26 -> 77340 | I26: =+'104_Synthèse'!I26+'105_Synthèse'!I26+'106_Synthèse'!I26 -> 77340 | ... M26: =+'104_Synthèse'!M26+'105_Synthèse'!M26+'106_Synthèse'!M26 -> 77340 | N26: =SUM(B26:M26) -> 928080 | O26: =+'104_Synthèse'!O26+'105_Synthèse'!O26++'106_Synthèse'!O26 -> 815705.55 | P26: =+N26-O26 -> 112374.45 | Q26: =+P26/O26 -> 0.13776349 | R26: ='106_Synthèse'!N26+'104_Synthèse'!N26+'105_Synthèse'!N26 -> 928080 | S26: =+N26-R26 -> 0
A27: Refact. HIJOS DE FEDERICO LIS | B27: =+'104_Synthèse'!B27+'105_Synthèse'!B27+'106_Synthèse'!B27 -> 0 | C27: =+'104_Synthèse'!C27+'105_Synthèse'!C27+'106_Synthèse'!C27 -> 0 | D27: =+'104_Synthèse'!D27+'105_Synthèse'!D27+'106_Synthèse'!D27 -> 0 | E27: =+'104_Synthèse'!E27+'105_Synthèse'!E27+'106_Synthèse'!E27 -> 0 | F27: =+'104_Synthèse'!F27+'105_Synthèse'!F27+'106_Synthèse'!F27 -> 0 | G27: =+'104_Synthèse'!G27+'105_Synthèse'!G27+'106_Synthèse'!G27 -> 0 | H27: =+'104_Synthèse'!H27+'105_Synthèse'!H27+'106_Synthèse'!H27 -> 0 | I27: =+'104_Synthèse'!I27+'105_Synthèse'!I27+'106_Synthèse'!I27 -> 0 | ... M27: =+'104_Synthèse'!M27+'105_Synthèse'!M27+'106_Synthèse'!M27 -> 0 | N27: =SUM(B27:M27) -> 0 | O27: =+'104_Synthèse'!O27+'105_Synthèse'!O27++'106_Synthèse'!O27 -> 396966.06 | P27: =+N27-O27 -> -396966.06 | Q27: =+P27/O27 -> -1 | R27: ='106_Synthèse'!N27+'104_Synthèse'!N27+'105_Synthèse'!N27 -> 0 | S27: =+N27-R27 -> 0
A28: Transport | B28: =+'104_Synthèse'!B28+'105_Synthèse'!B28+'106_Synthèse'!B28 -> 0 | C28: =+'104_Synthèse'!C28+'105_Synthèse'!C28+'106_Synthèse'!C28 -> 0 | D28: =+'104_Synthèse'!D28+'105_Synthèse'!D28+'106_Synthèse'!D28 -> 0 | E28: =+'104_Synthèse'!E28+'105_Synthèse'!E28+'106_Synthèse'!E28 -> 0 | F28: =+'104_Synthèse'!F28+'105_Synthèse'!F28+'106_Synthèse'!F28 -> 23025000 | G28: =+'104_Synthèse'!G28+'105_Synthèse'!G28+'106_Synthèse'!G28 -> 17268750 | H28: =+'104_Synthèse'!H28+'105_Synthèse'!H28+'106_Synthèse'!H28 -> 17268750 | I28: =+'104_Synthèse'!I28+'105_Synthèse'!I28+'106_Synthèse'!I28 -> 23025000 | ... M28: =+'104_Synthèse'!M28+'105_Synthèse'!M28+'106_Synthèse'!M28 -> 5756250 | N28: =SUM(B28:M28) -> 1.3239375e+08 | O28: =+'104_Synthèse'!O28+'105_Synthèse'!O28++'106_Synthèse'!O28 -> 142933 | P28: =+N28-O28 -> 1.3225082e+08 | Q28: =+P28/O28 -> 925.2644 | R28: ='106_Synthèse'!N28+'104_Synthèse'!N28+'105_Synthèse'!N28 -> 1.3239375e+08 | S28: =+N28-R28 -> 0
A29: Autres frais généraux | B29: =+'104_Synthèse'!B29+'105_Synthèse'!B29+'106_Synthèse'!B29 -> 190150 | C29: =+'104_Synthèse'!C29+'105_Synthèse'!C29+'106_Synthèse'!C29 -> 9550 | D29: =+'104_Synthèse'!D29+'105_Synthèse'!D29+'106_Synthèse'!D29 -> 9550 | E29: =+'104_Synthèse'!E29+'105_Synthèse'!E29+'106_Synthèse'!E29 -> 9550 | F29: =+'104_Synthèse'!F29+'105_Synthèse'!F29+'106_Synthèse'!F29 -> 9550 | G29: =+'104_Synthèse'!G29+'105_Synthèse'!G29+'106_Synthèse'!G29 -> 9550 | H29: =+'104_Synthèse'!H29+'105_Synthèse'!H29+'106_Synthèse'!H29 -> 13750 | I29: =+'104_Synthèse'!I29+'105_Synthèse'!I29+'106_Synthèse'!I29 -> 9550 | ... M29: =+'104_Synthèse'!M29+'105_Synthèse'!M29+'106_Synthèse'!M29 -> 9550 | N29: =SUM(B29:M29) -> 314400 | O29: =+'104_Synthèse'!O29+'105_Synthèse'!O29++'106_Synthèse'!O29 -> 195350.25 | P29: =+N29-O29 -> 119049.75 | Q29: =+P29/O29 -> 0.60941693 | R29: ='106_Synthèse'!N29+'104_Synthèse'!N29+'105_Synthèse'!N29 -> 314400 | S29: =+N29-R29 -> 0
A30: Coût de revient total | B30: =SUM(B22:B29)+B21+B18 -> #DIV/0! | C30: =SUM(C22:C29)+C21+C18 -> #DIV/0! | D30: =SUM(D22:D29)+D21+D18 -> #DIV/0! | E30: =SUM(E22:E29)+E21+E18 -> #DIV/0! | F30: =SUM(F22:F29)+F21+F18 -> #DIV/0! | G30: =SUM(G22:G29)+G21+G18 -> #DIV/0! | H30: =SUM(H22:H29)+H21+H18 -> #DIV/0! | I30: =SUM(I22:I29)+I21+I18 -> #DIV/0! | ... M30: =SUM(M22:M29)+M21+M18 -> #DIV/0! | N30: =SUM(B30:M30) -> #DIV/0! | O30: =SUM(O22:O29)+O21+O18 -> 12582357 | P30: =+N30-O30 -> #DIV/0! | Q30: =+P30/O30 -> #DIV/0! | R30: ='106_Synthèse'!N30+'104_Synthèse'!N30+'105_Synthèse'!N30 -> #DIV/0! | S30: =+N30-R30 -> #DIV/0!
A31: EBITDA | B31: =B11-B30 -> #DIV/0! | C31: =C11-C30 -> #DIV/0! | D31: =D11-D30 -> #DIV/0! | E31: =E11-E30 -> #DIV/0! | F31: =F11-F30 -> #DIV/0! | G31: =G11-G30 -> #DIV/0! | H31: =H11-H30 -> #DIV/0! | I31: =I11-I30 -> #DIV/0! | ... O31: =O11-O30 -> 221600.11 | P31: =+N31-O31 -> #DIV/0! | Q31: =+P31/O31 -> #DIV/0! | R31: ='106_Synthèse'!N31+'104_Synthèse'!N31+'105_Synthèse'!N31 -> #DIV/0! | S31: =+N31-R31 -> #DIV/0!
A32: Amortissements | B32: =+'104_Synthèse'!B32+'105_Synthèse'!B32+'106_Synthèse'!B32 -> 240339.33 | C32: =+'104_Synthèse'!C32+'105_Synthèse'!C32+'106_Synthèse'!C32 -> 240339.33 | D32: =+'104_Synthèse'!D32+'105_Synthèse'!D32+'106_Synthèse'!D32 -> 240339.33 | E32: =+'104_Synthèse'!E32+'105_Synthèse'!E32+'106_Synthèse'!E32 -> 240339.33 | F32: =+'104_Synthèse'!F32+'105_Synthèse'!F32+'106_Synthèse'!F32 -> 240339.33 | G32: =+'104_Synthèse'!G32+'105_Synthèse'!G32+'106_Synthèse'!G32 -> 240339.33 | H32: =+'104_Synthèse'!H32+'105_Synthèse'!H32+'106_Synthèse'!H32 -> 240339.33 | I32: =+'104_Synthèse'!I32+'105_Synthèse'!I32+'106_Synthèse'!I32 -> 240339.33 | ... M32: =+'104_Synthèse'!M32+'105_Synthèse'!M32+'106_Synthèse'!M32 -> 243355.16 | N32: =SUM(B32:M32) -> 2893119.4 | O32: =+'104_Synthèse'!O32+'105_Synthèse'!O32++'106_Synthèse'!O32 -> 2724261.2 | P32: =+N32-O32 -> 168858.2 | Q32: =+P32/O32 -> 0.061983115 | R32: ='106_Synthèse'!N32+'104_Synthèse'!N32+'105_Synthèse'!N32 -> 2893119.4 | S32: =+N32-R32 -> 0
A33: Résultat d'exploitation | B33: =B31-B32 -> #DIV/0! | C33: =C31-C32 -> #DIV/0! | D33: =D31-D32 -> #DIV/0! | E33: =E31-E32 -> #DIV/0! | F33: =F31-F32 -> #DIV/0! | G33: =G31-G32 -> #DIV/0! | H33: =H31-H32 -> #DIV/0! | I33: =I31-I32 -> #DIV/0! | ... O33: =O31-O32 -> -2502661.1 | P33: =+N33-O33 -> #DIV/0! | Q33: =+P33/O33 -> #DIV/0! | R33: ='106_Synthèse'!N33+'104_Synthèse'!N33+'105_Synthèse'!N33 -> #DIV/0! | S33: =+N33-R33 -> #DIV/0!
A34: Résultat net en % du CA | N34: =+N33/N7 -> #DIV/0! | O34: =+O33/O7 -> -0.22217614 | P34: =+N34-O34 -> #DIV/0!
A35: EBITDA en % du CA | N35: =+N31/N7 -> #DIV/0! | O35: =+O31/O7 -> 0.019672762 | P35: =+N35-O35 -> #DIV/0!
A36: PMV au kg | B36: =+(B7)/B5 -> #DIV/0! | C36: =+(C7)/C5 -> #DIV/0! | D36: =+(D7)/D5 -> #DIV/0! | E36: =+(E7)/E5 -> 0 | F36: =+(F7)/F5 -> 0.028335253 | G36: =+(G7)/G5 -> 0.028335253 | H36: =+(H7)/H5 -> 0.028335253 | I36: =+(I7)/I5 -> 0.028335253 | ... O36: =+(O7)/O5 -> 5.6804578 | P36: =+N36-O36 -> -5.6563102 | Q36: =+P36/O36 -> -0.99574901 | S36: =+'104_Synthèse'!O33+'105_Synthèse'!O33+'106_Synthèse'!O33 -> -2502661.1
A37: CA à l'hectare prod | B37: =+B7/B4 -> 0 | C37: =+C7/C4 -> 0 | D37: =+D7/D4 -> 0 | E37: =+E7/E4 -> 0 | F37: =+F7/F4 -> 117444.53 | G37: =+G7/G4 -> 88083.397 | H37: =+H7/H4 -> 88083.397 | I37: =+I7/I4 -> 117444.53 | ... O37: =+O7/O4 -> 651116.24 | P37: =+N37-O37 -> 24189.806 | Q37: =+P37/O37 -> 0.037151287 | S37: =+O33-S36 -> 0
A38: Coût à l'hectare prod (hors Amort) | B38: =+(B30-B10)/B4 -> #DIV/0! | C38: =+(C30-C10)/C4 -> #DIV/0! | D38: =+(D30-D10)/D4 -> #DIV/0! | E38: =+(E30-E10)/E4 -> #DIV/0! | F38: =+(F30-F10)/F4 -> #DIV/0! | G38: =+(G30-G10)/G4 -> #DIV/0! | H38: =+(H30-H10)/H4 -> #DIV/0! | I38: =+(I30-I10)/I4 -> #DIV/0! | ... O38: =+(O30-O10)/O4 -> 727303.86 | P38: =+N38-O38 -> #DIV/0! | Q38: =+P38/O38 -> #DIV/0!
A39: EBITDA à l'hectare prod | B39: =+B31/B4 -> #DIV/0! | C39: =+C31/C4 -> #DIV/0! | D39: =+D31/D4 -> #DIV/0! | E39: =+E31/E4 -> #DIV/0! | F39: =+F31/F4 -> #DIV/0! | G39: =+G31/G4 -> #DIV/0! | H39: =+H31/H4 -> #DIV/0! | I39: =+I31/I4 -> #DIV/0! | ... O39: =+O31/O4 -> 12809.255 | P39: =+N39-O39 -> #DIV/0! | Q39: =+P39/O39 -> #DIV/0!
A40: Coût total à l'hectare prod | B40: =+(B30+B32-B10)/B4 -> #DIV/0! | C40: =+(C30+C32-C10)/C4 -> #DIV/0! | D40: =+(D30+D32-D10)/D4 -> #DIV/0! | E40: =+(E30+E32-E10)/E4 -> #DIV/0! | F40: =+(F30+F32-F10)/F4 -> #DIV/0! | G40: =+(G30+G32-G10)/G4 -> #DIV/0! | H40: =+(H30+H32-H10)/H4 -> #DIV/0! | I40: =+(I30+I32-I10)/I4 -> #DIV/0! | ... O40: =+(O30+O32-O10)/O4 -> 884775.61 | P40: =+N40-O40 -> #DIV/0! | Q40: =+P40/O40 -> #DIV/0!
...

Sheet Feuil1

Sheet 104_Synthèse
B1: BUD | C1: BUD | D1: BUD | E1: BUD | F1: BUD | G1: BUD | H1: BUD | I1: BUD | J1: BUD | K1: BUD | L1: BUD | M1: BUD | N1: BUD | O1: REEL | P1: VARIATION | Q1: VARIATION
A2: 104 - Analyse totale (MAD) | B2: 45839 | C2: =+B2+31 -> 45870 | D2: =+C2+31 -> 45901 | E2: =+D2+31 -> 45932 | F2: =+E2+31 -> 45963 | G2: =+F2+31 -> 45994 | H2: =+G2+31 -> 46025 | I2: =+H2+31 -> 46056 | J2: =+I2+31 -> 46087 | ... M2: =+L2+31 -> 46180 | N2: 19/20 | O2: 18/19 | P2: BUD-REEL | Q2: % | R2: source | S2: check
A3: Sup Tot (ha) | B3: =+'Plan de culture 104 '!$B$3 -> 0 | C3: =+'Plan de culture 104 '!$B$3 -> 0 | D3: =+'Plan de culture 104 '!$B$3 -> 0 | E3: =+'Plan de culture 104 '!$B$3 -> 0 | F3: =+'Plan de culture 104 '!$B$3 -> 0 | G3: =+'Plan de culture 104 '!$B$3 -> 0 | H3: =+'Plan de culture 104 '!$B$3 -> 0 | I3: =+'Plan de culture 104 '!$B$3 -> 0 | ... N3: =+'Plan de culture 104 '!$B$3 -> 0 | O3: 6.8 | P3: =+N3-O3 -> -6.8 | Q3: =+P3/O3 -> -1 | R3: =+'Plan de culture 104 '!$B$3 -> 0 | S3: =+N3-R3 -> 0
A4: Sup productive | B4: ='Plan de culture 104 '!$C$3 -> 15.35 | C4: ='Plan de culture 104 '!$C$3 -> 15.35 | D4: ='Plan de culture 104 '!$C$3 -> 15.35 | E4: ='Plan de culture 104 '!$C$3 -> 15.35 | F4: ='Plan de culture 104 '!$C$3 -> 15.35 | G4: ='Plan de culture 104 '!$C$3 -> 15.35 | H4: ='Plan de culture 104 '!$C$3 -> 15.35 | I4: ='Plan de culture 104 '!$C$3 -> 15.35 | ... N4: ='Plan de culture 104 '!$C$3 -> 15.35 | O4: 6.8 | P4: =+N4-O4 -> 8.55 | Q4: =+P4/O4 -> 1.2573529 | R4: =+'Budget Volumes Export'!N8 -> 15.35 | S4: =+N4-R4 -> 0
A5: Vol (kg) | B5: =+'Budget Volumes Export'!B7+'Budget Volumes ML'!B7 -> 0 | C5: =+'Budget Volumes Export'!C7+'Budget Volumes ML'!C7 -> 0 | D5: =+'Budget Volumes Export'!D7+'Budget Volumes ML'!D7 -> 0 | E5: =+'Budget Volumes Export'!E7+'Budget Volumes ML'!E7 -> 30700 | F5: =+'Budget Volumes Export'!F7+'Budget Volumes ML'!F7 -> 337700 | G5: =+'Budget Volumes Export'!G7+'Budget Volumes ML'!G7 -> 253275 | H5: =+'Budget Volumes Export'!H7+'Budget Volumes ML'!H7 -> 253275 | I5: =+'Budget Volumes Export'!I7+'Budget Volumes ML'!I7 -> 337700 | ... M5: =+'Budget Volumes Export'!M7+'Budget Volumes ML'!M7 -> 84425 | N5: =SUM(B5:M5) -> 1972475 | O5: 1108263.7 | P5: =+N5-O5 -> 864211.32 | Q5: =+P5/O5 -> 0.77978854 | R5: =+'Budget Volumes Export'!N7*1000 -> 1.76525e+09 | S5: =+N5-R5 -> -1.7632775e+09
A6: rendement (t/ha) | B6: ='Budget Volumes Export'!B9+'Budget Volumes ML'!B9 -> 0 | C6: ='Budget Volumes Export'!C9+'Budget Volumes ML'!C9 -> 0 | D6: ='Budget Volumes Export'!D9+'Budget Volumes ML'!D9 -> 0 | E6: ='Budget Volumes Export'!E9+'Budget Volumes ML'!E9 -> 2000 | F6: ='Budget Volumes Export'!F9+'Budget Volumes ML'!F9 -> 22000 | G6: ='Budget Volumes Export'!G9+'Budget Volumes ML'!G9 -> 16500 | H6: ='Budget Volumes Export'!H9+'Budget Volumes ML'!H9 -> 16500 | I6: ='Budget Volumes Export'!I9+'Budget Volumes ML'!I9 -> 22000 | ... N6: ='Budget Volumes Export'!N9+'Budget Volumes ML'!N9 -> 128500 | O6: =+O5/O4/1000 -> 162.97995 | P6: =+N6-O6 -> 128337.02 | Q6: =+P6/O6 -> 787.44053 | R6: =+R5/R4/1000 -> 115000 | S6: =+N6-R6 -> 13500
A7: CA EXPORT(MAD) | B7: =+'Budget Commercial Export'!B7 -> 0 | C7: =+'Budget Commercial Export'!C7 -> 0 | D7: =+'Budget Commercial Export'!D7 -> 0 | E7: =+'Budget Commercial Export'!E7 -> 0 | F7: =+'Budget Commercial Export'!F7 -> 3070000 | G7: =+'Budget Commercial Export'!G7 -> 2302500 | H7: =+'Budget Commercial Export'!H7 -> 2302500 | I7: =+'Budget Commercial Export'!I7 -> 3070000 | ... M7: =+'Budget Commercial Export'!M7 -> 767500 | N7: =SUM(B7:M7) -> 17652500 | O7: 2538893.7 | P7: =+N7-O7 -> 15113606 | Q7: =+P7/O7 -> 5.9528315 | R7: =+'Budget Commercial Export'!N7 -> 17652500 | S7: =+N7-R7 -> 0
A8: CA MARCHE LOCAL(MAD) | B8: =+'Budget Commercial ML'!B7 -> 0 | C8: =+'Budget Commercial ML'!C7 -> 0 | D8: =+'Budget Commercial ML'!D7 -> 0 | E8: =+'Budget Commercial ML'!E7 -> 30700 | F8: =+'Budget Commercial ML'!F7 -> 30700 | G8: =+'Budget Commercial ML'!G7 -> 23025 | H8: =+'Budget Commercial ML'!H7 -> 23025 | I8: =+'Budget Commercial ML'!I7 -> 30700 | ... M8: =+'Budget Commercial ML'!M7 -> 7675 | N8: =SUM(B8:M8) -> 207225 | O8: 0 | P8: =+N8-O8 -> 207225 | Q8: =+P8/O8 -> #DIV/0!
A9: Autres revenus (MAD) | N9: =SUM(B9:M9) -> 0 | O9: 1023632.5 | P9: =+N9-O9 -> -1023632.5 | Q9: =+P9/O9 -> -1
A10: Production encours (MAD) | B10: =SUM(B68:B82) -> #DIV/0! | C10: =SUM(C68:C82) -> #DIV/0! | D10: =SUM(D68:D82) -> #DIV/0! | E10: =+E66 -> #DIV/0! | F10: =+F66 -> #DIV/0! | G10: =+G66 -> #DIV/0! | H10: =+H66 -> #DIV/0! | I10: =+I66 -> #DIV/0! | J10: =+J66 -> #DIV/0! | K10: =+K66 -> #DIV/0! | L10: =+L66 -> #DIV/0! | M10: =+M66 -> #DIV/0! | N10: =SUM(B10:M10) -> #DIV/0! | O10: 0 | P10: =+N10-O10 -> #DIV/0! | Q10: =+P10/O10 -> #DIV/0! | R10: 0 | S10: =+N10-R10 -> #DIV/0!
A11: Production totale (MAD) | B11: =+B10+B7+B9 -> #DIV/0! | C11: =+C10+C7+C9 -> #DIV/0! | D11: =+D10+D7+D9 -> #DIV/0! | E11: =+E10+E7+E9 -> #DIV/0! | F11: =+F10+F7+F9 -> #DIV/0! | G11: =+G10+G7+G9 -> #DIV/0! | H11: =+H10+H7+H9 -> #DIV/0! | I11: =+I10+I7+I9 -> #DIV/0! | ... M11: =+M10+M7+M9 -> #DIV/0! | N11: =SUM(B11:M11) -> #DIV/0! | O11: =+O10+O7+O9 -> 3562526.2 | P11: =+N11-O11 -> #DIV/0! | Q11: =+P11/O11 -> #DIV/0!
A12: Consommation Semences | B12: =+'Budget Semences'!B7 -> 0 | C12: =+'Budget Semences'!C10 -> 1494600 | D12: =+'Budget Semences'!D10 -> 0 | E12: =+'Budget Semences'!E10 -> 0 | F12: =+'Budget Semences'!F10 -> 0 | G12: =+'Budget Semences'!G10 -> 0 | H12: =+'Budget Semences'!H10 -> 0 | I12: =+'Budget Semences'!I10 -> 0 | J12: =+'Budget Semences'!J10 -> 0 | ... M12: =+'Budget Semences'!M10 -> 0 | N12: =SUM(B12:M12) -> 1494600 | O12: 202400 | P12: =+N12-O12 -> 1292200 | Q12: =+P12/O12 -> 6.3843874 | R12: =+'Budget Semences'!N7 -> 1494600 | S12: =+N12-R12 -> 0
A13: Consommation Engrais | B13: =+'Budget Engrais'!B7 -> 0 | C13: =+'Budget Engrais'!C7 -> 0 | D13: =+'Budget Engrais'!D7 -> 0 | E13: =+'Budget Engrais'!E7 -> 0 | F13: =+'Budget Engrais'!F7 -> 0 | G13: =+'Budget Engrais'!G7 -> 0 | H13: =+'Budget Engrais'!H7 -> 0 | I13: =+'Budget Engrais'!I7 -> 0 | ... M13: =+'Budget Engrais'!M7 -> 0 | N13: =SUM(B13:M13) -> 0 | O13: 537520.18 | P13: =+N13-O13 -> -537520.18 | Q13: =+P13/O13 -> -1 | R13: =+'Budget Engrais'!N7 -> 0 | S13: =+N13-R13 -> 0
A14: Consommation Plants | B14: =+'Budget Plants'!B7 -> 0 | C14: =+'Budget Plants'!C7 -> 1113000 | D14: =+'Budget Plants'!D7 -> 0 | E14: =+'Budget Plants'!E7 -> 0 | F14: =+'Budget Plants'!F7 -> 0 | G14: =+'Budget Plants'!G7 -> 0 | H14: =+'Budget Plants'!H7 -> 0 | I14: =+'Budget Plants'!I7 -> 0 | ... M14: =+'Budget Plants'!M7 -> 0 | N14: =SUM(B14:M14) -> 1113000 | O14: 254887 | P14: =+N14-O14 -> 858113 | Q14: =+P14/O14 -> 3.3666409 | R14: =+'Budget Plants'!N7 -> 1113000 | S14: =+N14-R14 -> 0
A15: Consommation Phytos | B15: =+'Budget Phytos'!B7 -> 0 | C15: =+'Budget Phytos'!C7 -> 0 | D15: =+'Budget Phytos'!D7 -> 0 | E15: =+'Budget Phytos'!E7 -> 0 | F15: =+'Budget Phytos'!F7 -> 0 | G15: =+'Budget Phytos'!G7 -> 0 | H15: =+'Budget Phytos'!H7 -> 0 | I15: =+'Budget Phytos'!I7 -> 0 | ... M15: =+'Budget Phytos'!M7 -> 0 | N15: =SUM(B15:M15) -> 0 | O15: 582668.22 | P15: =+N15-O15 -> -582668.22 | Q15: =+P15/O15 -> -1 | R15: =+'Budget Phytos'!N7 -> 0 | S15: =+N15-R15 -> 0
A16: Consommation Insectes | B16: =+'Budget Ruches'!B7 -> 0 | C16: =+'Budget Ruches'!C7 -> 0 | D16: =+'Budget Ruches'!D7 -> 0 | E16: =+'Budget Ruches'!E7 -> 0 | F16: =+'Budget Ruches'!F7 -> 0 | G16: =+'Budget Ruches'!G7 -> 0 | H16: =+'Budget Ruches'!H7 -> 0 | I16: =+'Budget Ruches'!I7 -> 0 | ... M16: =+'Budget Ruches'!M7 -> 0 | N16: =SUM(B16:M16) -> 0 | O16: 107635.05 | P16: =+N16-O16 -> -107635.05 | Q16: =+P16/O16 -> -1 | R16: =+'Budget Ruches'!N7 -> 0 | S16: =+N16-R16 -> 0
A17: Autres fournitures agricoles | B17: =+'Budget Fres Agri'!B7 -> 479534 | C17: =+'Budget Fres Agri'!C7 -> 15350 | D17: =+'Budget Fres Agri'!D7 -> 15350 | E17: =+'Budget Fres Agri'!E7 -> 15350 | F17: =+'Budget Fres Agri'!F7 -> 15350 | G17: =+'Budget Fres Agri'!G7 -> 15350 | H17: =+'Budget Fres Agri'!H7 -> 15350 | I17: =+'Budget Fres Agri'!I7 -> 15350 | ... M17: =+'Budget Fres Agri'!M7 -> 15350 | N17: =SUM(B17:M17) -> 648384 | O17: 73551.904 | P17: =+N17-O17 -> 574832.1 | Q17: =+P17/O17 -> 7.8153258 | R17: =+'Budget Fres Agri'!N7 -> 648384 | S17: =+N17-R17 -> 0
A18: Total consommation Intrants | B18: =SUM(B12:B17) -> 479534 | C18: =SUM(C12:C17) -> 2622950 | D18: =SUM(D12:D17) -> 15350 | E18: =SUM(E12:E17) -> 15350 | F18: =SUM(F12:F17) -> 15350 | G18: =SUM(G12:G17) -> 15350 | H18: =SUM(H12:H17) -> 15350 | I18: =SUM(I12:I17) -> 15350 | ... M18: =SUM(M12:M17) -> 15350 | N18: =SUM(B18:M18) -> 3255984 | O18: =SUM(O12:O17) -> 1758662.4 | P18: =+N18-O18 -> 1497321.6 | Q18: =+P18/O18 -> 0.85139802 | R18: =+'Budget Semences'!N7+'Budget Plants'!N7+'Budget Engrais'!N7+'Budget Phytos'!N7+'Budget Ruches'!N7+'Budget Fres Agri'!N7 -> 3255984 | S18: =+N18-R18 -> 0
A19: Electricité | B19: =+'Budget Energie'!B15+'Budget Energie'!B22 -> 0 | C19: =+'Budget Energie'!C15+'Budget Energie'!C22 -> 0 | D19: =+'Budget Energie'!D15+'Budget Energie'!D22 -> 0 | E19: =+'Budget Energie'!E15+'Budget Energie'!E22 -> 0 | F19: =+'Budget Energie'!F15+'Budget Energie'!F22 -> 0 | G19: =+'Budget Energie'!G15+'Budget Energie'!G22 -> 0 | H19: =+'Budget Energie'!H15+'Budget Energie'!H22 -> 0 | I19: =+'Budget Energie'!I15+'Budget Energie'!I22 -> 0 | ... M19: =+'Budget Energie'!M15+'Budget Energie'!M22 -> 0 | N19: =SUM(B19:M19) -> 0 | O19: 91727.417 | P19: =+N19-O19 -> -91727.417 | Q19: =+P19/O19 -> -1 | R19: =+'Budget Energie'!N15+'Budget Energie'!N22 -> 0 | S19: =+N19-R19 -> 0
A20: Eau | B20: =+'Budget Energie'!B13+'Budget Energie'!B20 -> 0 | C20: =+'Budget Energie'!C13+'Budget Energie'!C20 -> 0 | D20: =+'Budget Energie'!D13+'Budget Energie'!D20 -> 0 | E20: =+'Budget Energie'!E13+'Budget Energie'!E20 -> 0 | F20: =+'Budget Energie'!F13+'Budget Energie'!F20 -> 0 | G20: =+'Budget Energie'!G13+'Budget Energie'!G20 -> 0 | H20: =+'Budget Energie'!H13+'Budget Energie'!H20 -> 0 | I20: =+'Budget Energie'!I13+'Budget Energie'!I20 -> 0 | ... M20: =+'Budget Energie'!M13+'Budget Energie'!M20 -> 0 | N20: =SUM(B20:M20) -> 0 | O20: 20637.641 | P20: =+N20-O20 -> -20637.641 | Q20: =+P20/O20 -> -1 | R20: =+'Budget Energie'!N13+'Budget Energie'!N20 -> 0 | S20: =+N20-R20 -> 0
A21: Total consommation Energie | B21: =SUM(B19:B20) -> 0 | C21: =SUM(C19:C20) -> 0 | D21: =SUM(D19:D20) -> 0 | E21: =SUM(E19:E20) -> 0 | F21: =SUM(F19:F20) -> 0 | G21: =SUM(G19:G20) -> 0 | H21: =SUM(H19:H20) -> 0 | I21: =SUM(I19:I20) -> 0 | ... M21: =SUM(M19:M20) -> 0 | N21: =SUM(B21:M21) -> 0 | O21: =+O20+O19 -> 112365.06 | P21: =+N21-O21 -> -112365.06 | Q21: =+P21/O21 -> -1 | R21: =+'Budget Energie'!N7 -> 0 | S21: =+N21-R21 -> 0
A22: Prestations & analyses | B22: =+'Budget Ent & Analyses'!B14+'Budget Commun'!B19+'Budget Ent & Analyses'!B22 -> 0 | C22: =+'Budget Ent & Analyses'!C14+'Budget Commun'!C19+'Budget Ent & Analyses'!C22 -> 61400 | D22: =+'Budget Ent & Analyses'!D14+'Budget Commun'!D19+'Budget Ent & Analyses'!D22 -> 0 | E22: =+'Budget Ent & Analyses'!E14+'Budget Commun'!E19+'Budget Ent & Analyses'!E22 -> 0 | F22: =+'Budget Ent & Analyses'!F14+'Budget Commun'!F19+'Budget Ent & Analyses'!F22 -> 0 | G22: =+'Budget Ent & Analyses'!G14+'Budget Commun'!G19+'Budget Ent & Analyses'!G22 -> 0 | H22: =+'Budget Ent & Analyses'!H14+'Budget Commun'!H19+'Budget Ent & Analyses'!H22 -> 0 | I22: =+'Budget Ent & Analyses'!I14+'Budget Commun'!I19+'Budget Ent & Analyses'!I22 -> 0 | ... M22: =+'Budget Ent & Analyses'!M14+'Budget Commun'!M19+'Budget Ent & Analyses'!M22 -> 0 | N22: =SUM(B22:M22) -> 61400 | O22: 43594.909 | P22: =+N22-O22 -> 17805.091 | Q22: =+P22/O22 -> 0.40842133 | R22: =+'Budget Ent & Analyses'!N14+'Budget Commun'!N19+'Budget Ent & Analyses'!N22 -> 61400 | S22: =+N22-R22 -> 0
A23: Loyers fermes | B23: =+'Budget Loyers Fermes'!B7 -> 37622.549 | C23: =+'Budget Loyers Fermes'!C7 -> 37622.549 | D23: =+'Budget Loyers Fermes'!D7 -> 37622.549 | E23: =+'Budget Loyers Fermes'!E7 -> 37622.549 | F23: =+'Budget Loyers Fermes'!F7 -> 37622.549 | G23: =+'Budget Loyers Fermes'!G7 -> 37622.549 | H23: =+'Budget Loyers Fermes'!H7 -> 37622.549 | I23: =+'Budget Loyers Fermes'!I7 -> 37622.549 | ... M23: =+'Budget Loyers Fermes'!M7 -> 37622.549 | N23: =SUM(B23:M23) -> 451470.59 | O23: 191666.67 | P23: =+N23-O23 -> 259803.92 | Q23: =+P23/O23 -> 1.3554987 | R23: =+'Budget Loyers Fermes'!N7 -> 451470.59 | S23: =+N23-R23 -> 0
A24: Entretien | B24: =+'Budget Ent & Analyses'!B7-'Budget Ent & Analyses'!B14-'Budget Ent & Analyses'!B22+'Budget Commun'!B27 -> 10295.303 | C24: =+'Budget Ent & Analyses'!C7-'Budget Ent & Analyses'!C14-'Budget Ent & Analyses'!C22+'Budget Commun'!C27 -> 14132.803 | D24: =+'Budget Ent & Analyses'!D7-'Budget Ent & Analyses'!D14-'Budget Ent & Analyses'!D22+'Budget Commun'!D27 -> 14132.803 | E24: =+'Budget Ent & Analyses'!E7-'Budget Ent & Analyses'!E14-'Budget Ent & Analyses'!E22+'Budget Commun'!E27 -> 10295.303 | F24: =+'Budget Ent & Analyses'!F7-'Budget Ent & Analyses'!F14-'Budget Ent & Analyses'!F22+'Budget Commun'!F27 -> 10295.303 | G24: =+'Budget Ent & Analyses'!G7-'Budget Ent & Analyses'!G14-'Budget Ent & Analyses'!G22+'Budget Commun'!G27 -> 14132.803 | H24: =+'Budget Ent & Analyses'!H7-'Budget Ent & Analyses'!H14-'Budget Ent & Analyses'!H22+'Budget Commun'!H27 -> 14132.803 | I24: =+'Budget Ent & Analyses'!I7-'Budget Ent & Analyses'!I14-'Budget Ent & Analyses'!I22+'Budget Commun'!I27 -> 10295.303 | ... M24: =+'Budget Ent & Analyses'!M7-'Budget Ent & Analyses'!M14-'Budget Ent & Analyses'!M22+'Budget Commun'!M27 -> 1257.8035 | N24: =SUM(B24:M24) -> 125618.64 | O24: 105442.18 | P24: =+N24-O24 -> 20176.466 | Q24: =+P24/O24 -> 0.19135101 | R24: ='Budget Ent & Analyses'!N7-'Budget Ent & Analyses'!N14-'Budget Ent & Analyses'!N22+'Budget Commun'!N27 -> 125618.64 | S24: =+N24-R24 -> 0
A25: Main d'œuvre Directe | B25: =+'Budget MOD'!B7 -> 354391.69 | C25: =+'Budget MOD'!C7 -> 309277.47 | D25: =+'Budget MOD'!D7 -> 277874.46 | E25: =+'Budget MOD'!E7 -> 277413.75 | F25: =+'Budget MOD'!F7 -> 271051.42 | G25: =+'Budget MOD'!G7 -> 261194.88 | H25: =+'Budget MOD'!H7 -> 259638.92 | I25: =+'Budget MOD'!I7 -> 259783.08 | ... M25: =+'Budget MOD'!M7 -> 6140 | N25: =SUM(B25:M25) -> 2548032.9 | O25: 1390695.8 | P25: =+N25-O25 -> 1157337.1 | Q25: =+P25/O25 -> 0.83220007 | R25: =+'Budget MOD'!N7 -> 2548032.9 | S25: =+N25-R25 -> 0
A26: Main d'œuvre Adm. | B26: =+'Budget Commun'!B54 -> 30399.538 | C26: =+'Budget Commun'!C54 -> 30399.538 | D26: =+'Budget Commun'!D54 -> 30399.538 | E26: =+'Budget Commun'!E54 -> 30399.538 | F26: =+'Budget Commun'!F54 -> 30399.538 | G26: =+'Budget Commun'!G54 -> 30399.538 | H26: =+'Budget Commun'!H54 -> 30399.538 | I26: =+'Budget Commun'!I54 -> 30399.538 | ... M26: =+'Budget Commun'!M54 -> 30399.538 | N26: =SUM(B26:M26) -> 364794.45 | O26: 319900.43 | P26: =+N26-O26 -> 44894.019 | Q26: =+P26/O26 -> 0.14033748 | R26: =+'Budget Commun'!N54 -> 364794.45 | S26: =+N26-R26 -> 0
A27: Refact. HIJOS DE FEDERICO LIS | B27: =+'Budget Commun'!B47 -> 0 | C27: =+'Budget Commun'!C47 -> 0 | D27: =+'Budget Commun'!D47 -> 0 | E27: =+'Budget Commun'!E47 -> 0 | F27: =+'Budget Commun'!F47 -> 0 | G27: =+'Budget Commun'!G47 -> 0 | H27: =+'Budget Commun'!H47 -> 0 | I27: =+'Budget Commun'!I47 -> 0 | ... M27: =+'Budget Commun'!M47 -> 0 | N27: =SUM(B27:M27) -> 0 | O27: 156940.07 | P27: =+N27-O27 -> -156940.07 | Q27: =+P27/O27 -> -1 | R27: =+'Budget Commun'!N47 -> 0 | S27: =+N27-R27 -> 0
A28: Transport | B28: =+'Budget Transp Ventes'!B7 -> 0 | C28: =+'Budget Transp Ventes'!C7 -> 0 | D28: =+'Budget Transp Ventes'!D7 -> 0 | E28: =+'Budget Transp Ventes'!E7 -> 0 | F28: =+'Budget Transp Ventes'!F7 -> 23025000 | G28: =+'Budget Transp Ventes'!G7 -> 17268750 | H28: =+'Budget Transp Ventes'!H7 -> 17268750 | I28: =+'Budget Transp Ventes'!I7 -> 23025000 | ... M28: =+'Budget Transp Ventes'!M7 -> 5756250 | N28: =SUM(B28:M28) -> 1.3239375e+08 | O28: 70540.186 | P28: =+N28-O28 -> 1.3232321e+08 | Q28: =+P28/O28 -> 1875.8557 | R28: =+'Budget Transp Ventes'!N7 -> 1.3239375e+08 | S28: =+N28-R28 -> 0
A29: Autres frais généraux | B29: =+'Budget Commun'!B43+'Budget Commun'!B34 -> 74741.04 | C29: =+'Budget Commun'!C43+'Budget Commun'!C34 -> 3753.7572 | D29: =+'Budget Commun'!D43+'Budget Commun'!D34 -> 3753.7572 | E29: =+'Budget Commun'!E43+'Budget Commun'!E34 -> 3753.7572 | F29: =+'Budget Commun'!F43+'Budget Commun'!F34 -> 3753.7572 | G29: =+'Budget Commun'!G43+'Budget Commun'!G34 -> 3753.7572 | H29: =+'Budget Commun'!H43+'Budget Commun'!H34 -> 5404.6243 | I29: =+'Budget Commun'!I43+'Budget Commun'!I34 -> 3753.7572 | ... M29: =+'Budget Commun'!M43+'Budget Commun'!M34 -> 3753.7572 | N29: =SUM(B29:M29) -> 123579.19 | O29: 79354.347 | P29: =+N29-O29 -> 44224.844 | Q29: =+P29/O29 -> 0.5573084 | R29: =+'Budget Commun'!N34+'Budget Commun'!N43 -> 123579.19 | S29: =+N29-R29 -> 0
A30: Coût de revient total | B30: =SUM(B22:B29)+B21+B18 -> 986984.12 | C30: =SUM(C22:C29)+C21+C18 -> 3079536.1 | D30: =SUM(D22:D29)+D21+D18 -> 379133.11 | E30: =SUM(E22:E29)+E21+E18 -> 374834.89 | F30: =SUM(F22:F29)+F21+F18 -> 23393473 | G30: =SUM(G22:G29)+G21+G18 -> 17631204 | H30: =SUM(H22:H29)+H21+H18 -> 17631298 | I30: =SUM(I22:I29)+I21+I18 -> 23382204 | ... M30: =SUM(M22:M29)+M21+M18 -> 5850773.6 | N30: =SUM(B30:M30) -> 1.3932463e+08 | O30: =SUM(O22:O29)+O21+O18 -> 4229162 | P30: =+N30-O30 -> 1.3509547e+08 | Q30: =+P30/O30 -> 31.943791
A31: EBITDA | B31: =B11-B30 -> #DIV/0! | C31: =C11-C30 -> #DIV/0! | D31: =D11-D30 -> #DIV/0! | E31: =E11-E30 -> #DIV/0! | F31: =F11-F30 -> #DIV/0! | G31: =G11-G30 -> #DIV/0! | H31: =H11-H30 -> #DIV/0! | I31: =I11-I30 -> #DIV/0! | ... O31: =O11-O30 -> -666635.78 | P31: =+N31-O31 -> #DIV/0! | Q31: =+P31/O31 -> #DIV/0!
A32: Amortissements | B32: =+'Budget Commun'!B14+'Budget Invest& Amort'!B9 -> 84231.686 | C32: =+'Budget Commun'!C14+'Budget Invest& Amort'!C9 -> 84231.686 | D32: =+'Budget Commun'!D14+'Budget Invest& Amort'!D9 -> 84231.686 | E32: =+'Budget Commun'!E14+'Budget Invest& Amort'!E9 -> 84231.686 | F32: =+'Budget Commun'!F14+'Budget Invest& Amort'!F9 -> 84231.686 | G32: =+'Budget Commun'!G14+'Budget Invest& Amort'!G9 -> 84231.686 | H32: =+'Budget Commun'!H14+'Budget Invest& Amort'!H9 -> 84231.686 | I32: =+'Budget Commun'!I14+'Budget Invest& Amort'!I9 -> 84231.686 | ... M32: =+'Budget Commun'!M14+'Budget Invest& Amort'!M9 -> 87247.519 | N32: =SUM(B32:M32) -> 1019827.7 | O32: 823053.01 | P32: =+N32-O32 -> 196774.71 | Q32: =+P32/O32 -> 0.23907903 | R32: =+'Budget Commun'!N14+'Budget Invest& Amort'!N9 -> 1019827.7 | S32: =+N32-R32 -> 0
A33: Résultat d'exploitation | B33: =B31-B32 -> #DIV/0! | C33: =C31-C32 -> #DIV/0! | D33: =D31-D32 -> #DIV/0! | E33: =E31-E32 -> #DIV/0! | F33: =F31-F32 -> #DIV/0! | G33: =G31-G32 -> #DIV/0! | H33: =H31-H32 -> #DIV/0! | I33: =I31-I32 -> #DIV/0! | ... O33: =O31-O32 -> -1489688.8 | P33: =+N33-O33 -> #DIV/0! | Q33: =+P33/O33 -> #DIV/0!
A34: EBITDA en % du CA | N34: =+N31/N7 -> #DIV/0! | O34: =+O31/O7 -> -0.26256939 | P34: =+N34-O34 -> #DIV/0!
A35: PMV au kg | B35: =+(B7)/B5 -> #DIV/0! | C35: =+(C7)/C5 -> #DIV/0! | D35: =+(D7)/D5 -> #DIV/0! | E35: =+(E7)/E5 -> 0 | F35: =+(F7)/F5 -> 9.0909091 | G35: =+(G7)/G5 -> 9.0909091 | H35: =+(H7)/H5 -> 9.0909091 | I35: =+(I7)/I5 -> 9.0909091 | ... O35: =+(O7)/O5 -> 2.2908751 | P35: =+N35-O35 -> 6.6585412 | Q35: =+P35/O35 -> 2.9065492
A36: CA à l'hectare prod | B36: =+B7/B4 -> 0 | C36: =+C7/C4 -> 0 | D36: =+D7/D4 -> 0 | E36: =+E7/E4 -> 0 | F36: =+F7/F4 -> 200000 | G36: =+G7/G4 -> 150000 | H36: =+H7/H4 -> 150000 | I36: =+I7/I4 -> 200000 | ... O36: =+O7/O4 -> 373366.72 | P36: =+N36-O36 -> 776633.28 | Q36: =+P36/O36 -> 2.0800817
A37: Coût à l'hectare prod (hors Amort) | B37: =+(B30-B10)/B4 -> #DIV/0! | C37: =+(C30-C10)/C4 -> #DIV/0! | D37: =+(D30-D10)/D4 -> #DIV/0! | E37: =+(E30-E10)/E4 -> #DIV/0! | F37: =+(F30-F10)/F4 -> #DIV/0! | G37: =+(G30-G10)/G4 -> #DIV/0! | H37: =+(H30-H10)/H4 -> #DIV/0! | I37: =+(I30-I10)/I4 -> #DIV/0! | ... O37: =+(O30-O10)/O4 -> 621935.58 | P37: =+N37-O37 -> #DIV/0! | Q37: =+P37/O37 -> #DIV/0!
A38: EBITDA à l'hectare prod | B38: =+B31/B4 -> #DIV/0! | C38: =+C31/C4 -> #DIV/0! | D38: =+D31/D4 -> #DIV/0! | E38: =+E31/E4 -> #DIV/0! | F38: =+F31/F4 -> #DIV/0! | G38: =+G31/G4 -> #DIV/0! | H38: =+H31/H4 -> #DIV/0! | I38: =+I31/I4 -> #DIV/0! | ... O38: =+O31/O4 -> -98034.674 | P38: =+N38-O38 -> #DIV/0! | Q38: =+P38/O38 -> #DIV/0!
A39: Coût total à l'hectare prod | B39: =+(B30+B32-B10)/B4 -> #DIV/0! | C39: =+(C30+C32-C10)/C4 -> #DIV/0! | D39: =+(D30+D32-D10)/D4 -> #DIV/0! | E39: =+(E30+E32-E10)/E4 -> #DIV/0! | F39: =+(F30+F32-F10)/F4 -> #DIV/0! | G39: =+(G30+G32-G10)/G4 -> #DIV/0! | H39: =+(H30+H32-H10)/H4 -> #DIV/0! | I39: =+(I30+I32-I10)/I4 -> #DIV/0! | ... O39: =+(O30+O32-O10)/O4 -> 742972.79 | P39: =+N39-O39 -> #DIV/0! | Q39: =+P39/O39 -> #DIV/0!
A40: REX à l'hectare prod | B40: =B33/B4 -> #DIV/0! | C40: =C33/C4 -> #DIV/0! | D40: =D33/D4 -> #DIV/0! | E40: =E33/E4 -> #DIV/0! | F40: =F33/F4 -> #DIV/0! | G40: =G33/G4 -> #DIV/0! | H40: =H33/H4 -> #DIV/0! | I40: =I33/I4 -> #DIV/0! | ... O40: =O33/O4 -> -219071.88 | P40: =+N40-O40 -> #DIV/0! | Q40: =+P40/O40 -> #DIV/0!
...

Sheet 105_Synthèse
B1: BUD | C1: BUD | D1: BUD | E1: BUD | F1: BUD | G1: BUD | H1: BUD | I1: BUD | J1: BUD | K1: BUD | L1: BUD | M1: BUD | N1: BUD | O1: REEL | P1: VARIATION | Q1: VARIATION
A2: 105 - Analyse totale (MAD) | B2: 45839 | C2: =+B2+31 -> 45870 | D2: =+C2+31 -> 45901 | E2: =+D2+31 -> 45932 | F2: =+E2+31 -> 45963 | G2: =+F2+31 -> 45994 | H2: =+G2+31 -> 46025 | I2: =+H2+31 -> 46056 | J2: =+I2+31 -> 46087 | ... M2: =+L2+31 -> 46180 | N2: 25/26 | O2: 25/26 | P2: BUD-REEL | Q2: % | R2: source | S2: check
